<?xml version="1.0" encoding="utf-8"?>
<!-- =================================================================================== -->
<!-- |    This document was autogenerated by xacro from comar_base.xacro               | -->
<!-- |    EDITING THIS FILE BY HAND IS NOT RECOMMENDED                                 | -->
<!-- =================================================================================== -->
<!--
  COMAR ROBOT ASELSAN 

  COMMENTED PARTS ARE USED FOR GAZEBOSIM
-->
<robot name="comar">
  <!--[Ns/m] -->
  <!-- [kg] -->
  <!--[N] -->
  <link name="base_link"> </link>
  <joint name="base_joint" type="fixed">
    <origin rpy="0 0 0" xyz="0 0 0"/>
    <parent link="base_link"/>
    <child link="base_link_inertia"/>
  </joint>
  <link name="base_link_inertia">
    <inertial>
      <mass value="18.596"/>
      <!-- [kg] -->
      <origin rpy="0 0 0" xyz="0 0 0"/>
      <inertia ixx="144005e-6" ixy="254013e-6" ixz="-1667.22e-6" iyy="380679e-6" iyz="1300.96e-6" izz="447682e-6"/>
    </inertial>
    <visual>
      <origin rpy="0 0 0" xyz="0 0 0"/>
      <geometry>
        <mesh filename="../meshes/ROBOT_GOVDE.stl"/>
      </geometry>
    </visual>
    <collision>
      <origin rpy="0 0 0" xyz="0 0 0"/>
      <geometry>
        <mesh filename="../meshes/ROBOT_GOVDE.stl"/>
      </geometry>
    </collision>
  </link>
  <!-- ================================================_LEG 1 - FR_======================================================== -->
  <joint name="abad_1_joint" type="revolute">
    <limit effort="50" lower="-3.1415" upper="3.1415" velocity="1000"/>
    <dynamics damping="0.03" friction="0.05"/>
    <origin rpy="1.5707845 0 1.5707845" xyz="222.50e-3 -65.50e-3 0"/>
    <axis xyz="0 0 1"/>
    <parent link="base_link"/>
    <child link="abad_1"/>
  </joint>
  <link name="abad_1">
    <inertial>
      <origin xyz="7.729e-3 4.8783e-3 -11.3664e-3"/>
      <mass value="0.8602"/>
      <!-- [kg] -->
      <inertia ixx="825001e-6" ixy="191012e-6" ixz="-799995e-6" iyy="998292e-6" iyz="485664e-6" izz="1292.28e-6"/>
    </inertial>
    <visual>
      <origin rpy="0 0 0" xyz="0 0 0"/>
      <geometry>
        <mesh filename="../meshes/ROBOT_ABDUCTION_FR.stl"/>
      </geometry>
    </visual>
    <collision>
      <origin rpy="0 0 0" xyz="0 0 0"/>
      <geometry>
        <mesh filename="../meshes/ROBOT_ABDUCTION_FR.stl"/>
      </geometry>
    </collision>
  </link>
  <joint name="hip_1_joint" type="revolute">
    <limit effort="50" lower="-3.1415" upper="3.1415" velocity="1000"/>
    <dynamics damping="0.03" friction="0.05"/>
    <origin rpy="1.5707845 -1.5707845 1.5707845" xyz="-15.5e-3 0 76.75e-3"/>
    <axis xyz="0 0 1"/>
    <parent link="abad_1"/>
    <child link="hip_1"/>
  </joint>
  <link name="hip_1">
    <inertial>
      <origin xyz="26.4228e-3 3.0919e-3 54.0237e-3"/>
      <mass value="1.3625"/>
      <inertia ixx="5507.92e-6" ixy="-510892e-6" ixz="-2820.18e-6" iyy="10901.5e-6" iyz="-348021e-6" izz="6784.8e-6"/>
    </inertial>
    <visual>
      <origin rpy="0 0 0" xyz="0 0 0"/>
      <geometry>
        <mesh filename="../meshes/ROBOT_HIP_R.stl"/>
      </geometry>
    </visual>
    <collision>
      <origin rpy="0 0 0" xyz="0 0 0"/>
      <geometry>
        <mesh filename="../meshes/ROBOT_HIP_R.stl"/>
      </geometry>
    </collision>
  </link>
  <joint name="knee_1_joint" type="revolute">
    <limit effort="50" lower="-3.1415" upper="3.1415" velocity="1000"/>
    <dynamics damping="0.03" friction="0.05"/>
    <origin rpy="0 0 0" xyz="200e-3 0 -80.24e-3"/>
    <axis xyz="0 0 1"/>
    <parent link="hip_1"/>
    <child link="knee_1"/>
  </joint>
  <link name="knee_1">
    <inertial>
      <origin xyz="138.023e-3 -7.0815e-3 0.9002e-3"/>
      <mass value="0.2967"/>
      <inertia ixx="71342e-6" ixy="294298e-6" ixz="-46.48e-6" iyy="7209.04e-6" iyz="2007e-6" izz="7242.60e-6"/>
    </inertial>
    <visual>
      <origin rpy="0 0 0" xyz="0 0 0"/>
      <geometry>
        <mesh filename="../meshes/ROBOT_KNEE.stl"/>
      </geometry>
    </visual>
    <collision>
      <origin rpy="0 0 0" xyz="0 0 0"/>
      <geometry>
        <mesh filename="../meshes/ROBOT_KNEE.stl"/>
      </geometry>
    </collision>
  </link>
  <!-- ================================================_LEG 2 - FL_======================================================== -->
  <joint name="abad_2_joint" type="revolute">
    <limit effort="50" lower="-3.1415" upper="3.1415" velocity="1000"/>
    <dynamics damping="0.03" friction="0.05"/>
    <origin rpy="1.5707845 0 1.5707845" xyz="222.50e-3 65.50e-3 0"/>
    <axis xyz="0 0 1"/>
    <parent link="base_link"/>
    <child link="abad_2"/>
  </joint>
  <link name="abad_2">
    <inertial>
      <origin xyz="7.729e-3 4.8783e-3 -11.3664e-3"/>
      <mass value="0.8602"/>
      <!-- [kg] -->
      <inertia ixx="825001e-6" ixy="-191012e-6" ixz="799995e-6" iyy="998292e-6" iyz="485664e-6" izz="1292.28e-6"/>
    </inertial>
    <visual>
      <origin rpy="0 0 0" xyz="0 0 0"/>
      <geometry>
        <mesh filename="../meshes/ROBOT_ABDUCTION_FL.stl"/>
      </geometry>
    </visual>
    <collision>
      <origin rpy="0 0 0" xyz="0 0 0"/>
      <geometry>
        <mesh filename="../meshes/ROBOT_ABDUCTION_FL.stl"/>
      </geometry>
    </collision>
  </link>
  <joint name="hip_2_joint" type="revolute">
    <limit effort="50" lower="-3.1415" upper="3.1415" velocity="1000"/>
    <dynamics damping="0.03" friction="0.05"/>
    <origin rpy="1.5707845 -1.5707845 1.5707845" xyz="15.5e-3 0 76.75e-3"/>
    <axis xyz="0 0 1"/>
    <parent link="abad_2"/>
    <child link="hip_2"/>
  </joint>
  <link name="hip_2">
    <inertial>
      <origin xyz="26.4228e-3 3.0919e-3 54.0237e-3"/>
      <mass value="1.3625"/>
      <inertia ixx="5507.92e-6" ixy="-510892e-6" ixz="2820.18e-6" iyy="10901.5e-6" iyz="348021e-6" izz="6784.8e-6"/>
    </inertial>
    <visual>
      <origin rpy="0 0 0" xyz="0 0 0"/>
      <geometry>
        <mesh filename="../meshes/ROBOT_HIP_L.stl"/>
      </geometry>
    </visual>
    <collision>
      <origin rpy="0 0 0" xyz="0 0 0"/>
      <geometry>
        <mesh filename="../meshes/ROBOT_HIP_L.stl"/>
      </geometry>
    </collision>
  </link>
  <joint name="knee_2_joint" type="revolute">
    <limit effort="50" lower="-3.1415" upper="3.1415" velocity="1000"/>
    <dynamics damping="0.03" friction="0.05"/>
    <origin rpy="0 0 0" xyz="200e-3 0 80.24e-3"/>
    <axis xyz="0 0 1"/>
    <parent link="hip_2"/>
    <child link="knee_2"/>
  </joint>
  <link name="knee_2">
    <inertial>
      <origin xyz="138.023e-3 -7.0815e-3 0.9002e-3"/>
      <mass value="0.2967"/>
      <inertia ixx="71342e-6" ixy="294298e-6" ixz="-46.48e-6" iyy="7209.04e-6" iyz="2007e-6" izz="7242.60e-6"/>
    </inertial>
    <visual>
      <origin rpy="0 0 0" xyz="0 0 0"/>
      <geometry>
        <mesh filename="../meshes/ROBOT_KNEE.stl"/>
      </geometry>
    </visual>
    <collision>
      <origin rpy="0 0 0" xyz="0 0 0"/>
      <geometry>
        <mesh filename="../meshes/ROBOT_KNEE.stl"/>
      </geometry>
    </collision>
  </link>
  <!-- ================================================_LEG 3 - HR_======================================================== -->
  <joint name="abad_3_joint" type="revolute">
    <limit effort="50" lower="-3.1415" upper="3.1415" velocity="1000"/>
    <dynamics damping="0.03" friction="0.05"/>
    <origin rpy="1.5707845 0 1.5707845" xyz="-222.50e-3 -65.50e-3 0"/>
    <axis xyz="0 0 1"/>
    <parent link="base_link"/>
    <child link="abad_3"/>
  </joint>
  <link name="abad_3">
    <inertial>
      <origin xyz="7.729e-3 4.8783e-3 -11.3664e-3"/>
      <mass value="0.8602"/>
      <!-- [kg] -->
      <inertia ixx="825001e-6" ixy="-191012e-6" ixz="-799995e-6" iyy="998292e-6" iyz="-485664e-6" izz="1292.28e-6"/>
    </inertial>
    <visual>
      <origin rpy="0 0 0" xyz="0 0 0"/>
      <geometry>
        <mesh filename="../meshes/ROBOT_ABDUCTION_HR.stl"/>
      </geometry>
    </visual>
    <collision>
      <origin rpy="0 0 0" xyz="0 0 0"/>
      <geometry>
        <mesh filename="../meshes/ROBOT_ABDUCTION_HR.stl"/>
      </geometry>
    </collision>
  </link>
  <joint name="hip_3_joint" type="revolute">
    <limit effort="50" lower="-3.1415" upper="3.1415" velocity="1000"/>
    <dynamics damping="0.03" friction="0.05"/>
    <origin rpy="1.5707845 -1.5707845 1.5707845" xyz="-15.5e-3 0 -76.75e-3"/>
    <axis xyz="0 0 1"/>
    <parent link="abad_3"/>
    <child link="hip_3"/>
  </joint>
  <link name="hip_3">
    <inertial>
      <origin xyz="26.4228e-3 3.0919e-3 54.0237e-3"/>
      <mass value="1.3625"/>
      <inertia ixx="5507.92e-6" ixy="-510892e-6" ixz="-2820.18e-6" iyy="10901.5e-6" iyz="-348021e-6" izz="6784.8e-6"/>
    </inertial>
    <visual>
      <origin rpy="0 0 0" xyz="0 0 0"/>
      <geometry>
        <mesh filename="../meshes/ROBOT_HIP_R.stl"/>
      </geometry>
    </visual>
    <collision>
      <origin rpy="0 0 0" xyz="0 0 0"/>
      <geometry>
        <mesh filename="../meshes/ROBOT_HIP_R.stl"/>
      </geometry>
    </collision>
  </link>
  <joint name="knee_3_joint" type="revolute">
    <limit effort="50" lower="-3.1415" upper="3.1415" velocity="1000"/>
    <dynamics damping="0.03" friction="0.05"/>
    <origin rpy="0 0 0" xyz="200e-3 0 -80.24e-3"/>
    <axis xyz="0 0 1"/>
    <parent link="hip_3"/>
    <child link="knee_3"/>
  </joint>
  <link name="knee_3">
    <inertial>
      <origin xyz="138.023e-3 -7.0815e-3 0.9002e-3"/>
      <mass value="0.2967"/>
      <inertia ixx="71342e-6" ixy="294298e-6" ixz="-46.48e-6" iyy="7209.04e-6" iyz="2007e-6" izz="7242.60e-6"/>
    </inertial>
    <visual>
      <origin rpy="0 0 0" xyz="0 0 0"/>
      <geometry>
        <mesh filename="../meshes/ROBOT_KNEE.stl"/>
      </geometry>
    </visual>
    <collision>
      <origin rpy="0 0 0" xyz="0 0 0"/>
      <geometry>
        <mesh filename="../meshes/ROBOT_KNEE.stl"/>
      </geometry>
    </collision>
  </link>
  <!-- ================================================_LEG 4 - HL_======================================================== -->
  <joint name="abad_4_joint" type="revolute">
    <limit effort="50" lower="-3.1415" upper="3.1415" velocity="1000"/>
    <dynamics damping="0.03" friction="0.05"/>
    <origin rpy="1.5707845 0 1.5707845" xyz="-222.50e-3 65.50e-3 0"/>
    <axis xyz="0 0 1"/>
    <parent link="base_link"/>
    <child link="abad_4"/>
  </joint>
  <link name="abad_4">
    <inertial>
      <origin xyz="7.729e-3 4.8783e-3 -11.3664e-3"/>
      <mass value="0.8602"/>
      <!-- [kg] -->
      <inertia ixx="825001e-6" ixy="191012e-6" ixz="799995e-6" iyy="998292e-6" iyz="-485664e-6" izz="1292.28e-6"/>
    </inertial>
    <visual>
      <origin rpy="0 0 0" xyz="0 0 0"/>
      <geometry>
        <mesh filename="../meshes/ROBOT_ABDUCTION_HL.stl"/>
      </geometry>
    </visual>
    <collision>
      <origin rpy="0 0 0" xyz="0 0 0"/>
      <geometry>
        <mesh filename="../meshes/ROBOT_ABDUCTION_HL.stl"/>
      </geometry>
    </collision>
  </link>
  <joint name="hip_4_joint" type="revolute">
    <limit effort="50" lower="-3.1415" upper="3.1415" velocity="1000"/>
    <dynamics damping="0.03" friction="0.05"/>
    <origin rpy="1.5707845 -1.5707845 1.5707845" xyz="15.5e-3 0 -76.75e-3"/>
    <axis xyz="0 0 1"/>
    <parent link="abad_4"/>
    <child link="hip_4"/>
  </joint>
  <link name="hip_4">
    <inertial>
      <origin xyz="26.4228e-3 3.0919e-3 54.0237e-3"/>
      <mass value="1.3625"/>
      <inertia ixx="5507.92e-6" ixy="-510892e-6" ixz="2820.18e-6" iyy="10901.5e-6" iyz="348021e-6" izz="6784.8e-6"/>
    </inertial>
    <visual>
      <origin rpy="0 0 0" xyz="0 0 0"/>
      <geometry>
        <mesh filename="../meshes/ROBOT_HIP_L.stl"/>
      </geometry>
    </visual>
    <collision>
      <origin rpy="0 0 0" xyz="0 0 0"/>
      <geometry>
        <mesh filename="../meshes/ROBOT_HIP_L.stl"/>
      </geometry>
    </collision>
  </link>
  <joint name="knee_4_joint" type="revolute">
    <limit effort="50" lower="-3.1415" upper="3.1415" velocity="1000"/>
    <dynamics damping="0.03" friction="0.05"/>
    <origin rpy="0 0 0" xyz="200e-3 0 80.24e-3"/>
    <axis xyz="0 0 1"/>
    <parent link="hip_4"/>
    <child link="knee_4"/>
  </joint>
  <link name="knee_4">
    <inertial>
      <origin xyz="138.023e-3 -7.0815e-3 0.9002e-3"/>
      <mass value="0.2967"/>
      <inertia ixx="71342e-6" ixy="294298e-6" ixz="-46.48e-6" iyy="7209.04e-6" iyz="2007e-6" izz="7242.60e-6"/>
    </inertial>
    <visual>
      <origin rpy="0 0 0" xyz="0 0 0"/>
      <geometry>
        <mesh filename="../meshes/ROBOT_KNEE.stl"/>
      </geometry>
    </visual>
    <collision>
      <origin rpy="0 0 0" xyz="0 0 0"/>
      <geometry>
        <mesh filename="../meshes/ROBOT_KNEE.stl"/>
      </geometry>
    </collision>
  </link>

    
</robot>

